Workbook

Sheet General
A2: OBS: Measurements before packing
A4: BoxType | B4: Length (m) | C4: Width (m) | D4: Height (m) | E4: Volume (L)
A5: Box 1 | B5: 0.2 | C5: 0.1 | D5: 0.05 | E5: =(B5*C5*D5)*1000 -> 1
A6: Box 2 | B6: 0.25 | C6: 0.15 | D6: 0.1 | E6: =(B6*C6*D6)*1000 -> 3.75
A7: Box 3 | B7: 0.3 | C7: 0.2 | D7: 0.1 | E7: =(B7*C7*D7)*1000 -> 6
A8: Box 4 | B8: 0.2 | C8: 0.2 | D8: 0.2 | E8: =(B8*C8*D8)*1000 -> 8
A11: Measurements performed by the algorithm (real time)
A13: BoxType | B13: Manual Volume (m³) | C13: Average Estimated Volume (L) | D13: RMSE (L) | E13: MAPE | F13: Standard deviation (L) | G13: Execution time (s) | H13: Column 8 | I13: Column 9
A14: Box 1 | B14: =E5 -> 1 | C14: ='Package 1 Evolution'!H56/10 -> 1.2247402 | D14: =SQRT('Package 1 Evolution'!I56/10) -> 0.24845211 | E14: ='Package 1 Evolution'!L56/10 -> 0.2247402 | F14: =SQRT('Package 1 Evolution'!J56/10) -> 0.10592589 | G14: ='Package 1 Evolution'!K56/10 -> 0.124
A15: Box 2 | B15: =E6 -> 3.75 | C15: ='Package 2 Evolution'!J61/15 -> 3.6453256 | D15: =SQRT('Package 2 Evolution'!K61/15) -> 0.18922484 | E15: ='Package 2 Evolution'!N61/15 -> 0.042723307 | F15: =SQRT('Package 2 Evolution'!L61/15) -> 0.15763664 | G15: ='Package 2 Evolution'!M61/15 -> 0.18133333
A16: Box 3 | B16: =E7 -> 6 | C16: ='Package 3 Evolution'!J58/12 -> 5.8305635 | D16: =SQRT('Package 3 Evolution'!K58/12) -> 0.4244294 | E16: ='Package 3 Evolution'!N58/12 -> 0.052034028 | F16: =SQRT('Package 3 Evolution'!L58/12) -> 0.38914212 | G16: ='Package 3 Evolution'!M58/12 -> 0.25666667
A17: Box 4 | B17: =E8 -> 8 | C17: ='Package 4 Evolution'!J52/10 -> 8.4797731 | D17: =SQRT('Package 4 Evolution'!K52/10) -> 1.0163743 | E17: ='Package 4 Evolution'!N52/10 -> 0.10163176 | F17: =SQRT('Package 4 Evolution'!L52/10) -> 0.8960103 | G17: ='Package 4 Evolution'!M52/10 -> 0.19
E19: MAPE - General | H19: =SUM('Package 1 Evolution'!L56+'Package 2 Evolution'!N61+'Package 3 Evolution'!N58+'Package 4 Evolution'!N52)/47 -> 0.096361225
E20: RMSE - General (L) | H20: =SQRT(('Package 1 Evolution'!I56+'Package 2 Evolution'!K61+'Package 3 Evolution'!K58+'Package 4 Evolution'!K52)/47) -> 0.53883692
E21: Standard deviation - Overall (L) | H21: =SQRT(('Package 1 Evolution'!J56+'Package 2 Evolution'!L61+'Package 3 Evolution'!L58+'Package 4 Evolution'!L52)/47) -> 0.46882529
E23: Average execution time | H23: =('Package 1 Evolution'!K56+'Package 2 Evolution'!M61+'Package 3 Evolution'!M58+'Package 4 Evolution'!M52)/47 -> 0.19021277
A25: BoxType | B25: Length (m) | C25: Column 3 | D25: Width (m) | E25: Column 2 | F25: Height (m) | G25: Column 3 2
B26: RMSE (m) | C26: Standard deviation | D26: RMSE (m) | E26: Standard deviation | F26: RMSE (m) | G26: Standard deviation
A27: Box 1 | B27: =SQRT('Package 1 Evolution'!P37/10) -> 0.010639549 | C27: =SQRT('Package 1 Evolution'!Q37/10) -> 0.010547038 | D27: =SQRT('Package 1 Evolution'!S37/10) -> 0.013034569 | E27: =SQRT('Package 1 Evolution'!T37/10) -> 0.0029342801 | F27: =SQRT('Package 1 Evolution'!V37/10) -> 0.0067453688 | G27: =SQRT('Package 1 Evolution'!W37/10) -> 0.0053563047
A28: Box 2 | B28: =SQRT('Package 2 Evolution'!P42/15) -> 0.0057271284 | C28: =SQRT('Package 2 Evolution'!Q42/15) -> 0.0057022413 | D28: =SQRT('Package 2 Evolution'!S42/15) -> 0.0098893883 | E28: =SQRT('Package 2 Evolution'!T42/15) -> 0.0046399234 | F28: =SQRT('Package 2 Evolution'!V42/15) -> 0.0082985943 | G28: =SQRT('Package 2 Evolution'!W42/15) -> 0.002434931
A29: Box 3 | B29: =SQRT('Package 3 Evolution'!P39/12) -> 0.01 | C29: =SQRT('Package 3 Evolution'!Q39/12) -> 0.0098305081 | D29: =SQRT('Package 3 Evolution'!S39/12) -> 0.013530829 | E29: =SQRT('Package 3 Evolution'!T39/12) -> 0.011091476 | F29: =SQRT('Package 3 Evolution'!V39/12) -> 0.0075718778 | G29: =SQRT('Package 3 Evolution'!W39/12) -> 0.0028867513
A30: Box 4 | B30: =SQRT('Package 4 Evolution'!P35/10) -> 0.020089798 | C30: =SQRT('Package 4 Evolution'!Q35/10) -> 0.011467716 | D30: =SQRT('Package 4 Evolution'!S35/10) -> 0.019063053 | E30: =SQRT('Package 4 Evolution'!T35/10) -> 0.01271849 | F30: =SQRT('Package 4 Evolution'!V35/10) -> 0.017955501 | G30: =SQRT('Package 4 Evolution'!W35/10) -> 0.0063371918
E32: RMSE - Overall (LxWxH) | G32: =SQRT(('Package 1 Evolution'!P37+'Package 1 Evolution'!S37+'Package 1 Evolution'!V37+'Package 2 Evolution'!P42+'Package 2 Evolution'!S42+'Package 2 Evolution'!V42+'Package 3 Evolution'!P39+'Package 3 Evolution'!S39+'Package 3 Evolution'!V39+'Package 4 Evolution'!P35+'Package 4 Evolution'!S35+'Package 4 Evolution'!V35)/(47*3)) -> 0.01227839
E33: Standard Deviation - General | G33: =SQRT(('Package 1 Evolution'!Q37+'Package 1 Evolution'!T37+'Package 1 Evolution'!W37+'Package 2 Evolution'!Q42+'Package 2 Evolution'!T42+'Package 2 Evolution'!W42+'Package 3 Evolution'!Q39+'Package 3 Evolution'!T39+'Package 3 Evolution'!W39+'Package 4 Evolution'!Q35+'Package 4 Evolution'!T35+'Package 4 Evolution'!W35)/(47*3)) -> 0.0077437697

Sheet Package 1 Evolution
A2: Note: The tables in this frame represent estimated values, plus a 5 mm precision adjustment implemented in the algorithm.
A4: Type of acquisition | B4: Execution Time (s) | C4: Length (m) | D4: Width (m) | E4: Height (m) | F4: Volume (L)
A5: MRS | B5: 0.09 | C5: 0.202 | D5: 0.12 | E5: 0.051 | F5: 1.238
A6: MRS | B6: 0.1 | C6: 0.212 | D6: 0.116 | E6: 0.05 | F6: 1.225
A7: MRS | B7: 0.09 | C7: 0.203 | D7: 0.11 | E7: 0.067 | F7: 1.503
A8: MRS | B8: 0.29 | C8: 0.205 | D8: 0.108 | E8: 0.051 | F8: 1.14
A9: MRS | B9: 0.1 | C9: 0.235 | D9: 0.113 | E9: 0.05 | F9: 1.331
A10: CR3 - Alone | B10: 0.14 | C10: 0.202 | D10: 0.111 | E10: 0.056 | F10: 1.253
A11: CR3 - Alone | B11: 0.11 | C11: 0.21 | D11: 0.11 | E11: 0.056 | F11: 1.296
A12: CR3 - Alone | B12: 0.12 | C12: 0.199 | D12: 0.114 | E12: 0.056 | F12: 1.27
A13: CR3 - Alone | B13: 0.12 | C13: 0.199 | D13: 0.112 | E13: 0.055 | F13: 1.226
A14: CR3 - Alone | B14: 0.08 | C14: 0.197 | D14: 0.118 | E14: 0.054 | F14: 1.243
J19: Note: The tables in this frame represent the estimated actual values, disregarding the 5 mm precision adjustment in the algorithm.
H20: Precision adjustment (m)= | I20: 0.005 | M20: Conversion factor (L) = | N20: 1000
I21: Attempt | J21: Length (m) | K21: Width (m) | L21: Height (m) | M21: Volume (L) | P21: Manual measurements
I22: 1 | J22: =C5-$I$20 -> 0.197 | K22: =D5-$I$20 -> 0.115 | L22: =E5-$I$20 -> 0.046 | M22: =(J22*K22*L22)*N$20 -> 1.04213 | P22: Length (m) | S22: Width (m) | V22: Height (m)
I23: 2 | J23: =C6-I$20 -> 0.207 | K23: =D6-J$20 -> 0.116 | L23: =E6-K$20 -> 0.05 | M23: =(J23*K23*L23)*N$20 -> 1.2006 | Q23: 0.2 | S23: 0.1 | V23: 0.05
I24: 3 | J24: =C7-I$20 -> 0.198 | K24: =D7-J$20 -> 0.11 | L24: =E7-K$20 -> 0.067 | M24: =(J24*K24*L24)*N$20 -> 1.45926 | P24: Mean squared error and standard deviation of the estimated box dimensions.
I25: 4 | J25: =C8-I$20 -> 0.2 | K25: =D8-J$20 -> 0.108 | L25: =E8-K$20 -> 0.051 | M25: =(J25*K25*L25)*N$20 -> 1.1016 | P25: Length | S25: Width | V25: Height
I26: 5 | J26: =C9-I$20 -> 0.23 | K26: =D9-J$20 -> 0.113 | L26: =E9-K$20 -> 0.05 | M26: =(J26*K26*L26)*N$20 -> 1.2995 | O26: Attempt | P26: SE (m) | Q26: Standard Deviation (m) | S26: SE (m) | T26: Standard Deviation (m) | V26: SE (m) | W26: Standard Deviation (m)
I27: 6 | J27: =C10-I$20 -> 0.197 | K27: =D10-J$20 -> 0.111 | L27: =E10-K$20 -> 0.056 | M27: =(J27*K27*L27)*N$20 -> 1.224552 | O27: 1 | P27: =abs(J22-Q$23)^2 -> 9e-06 | Q27: =ABS(J22-AVERAGE(J$22:J$31))^2 -> 1.936e-05 | S27: =abs(K22-S$23)^2 -> 0.000225 | T27: =ABS(K22-AVERAGE(K$22:K$31))^2 -> 5.29e-06 | V27: =abs(L22-V$23)^2 -> 1.6e-05 | W27: =ABS(L22-AVERAGE(L$22:L$31))^2 -> 6.561e-05
I28: 7 | J28: =C11-I$20 -> 0.205 | K28: =D11-J$20 -> 0.11 | L28: =E11-K$20 -> 0.056 | M28: =(J28*K28*L28)*N$20 -> 1.2628 | O28: 2 | P28: =abs(J23-Q$23)^2 -> 4.9e-05 | Q28: =ABS(J23-AVERAGE(J$22:J$31))^2 -> 3.136e-05 | S28: =abs(K23-S$23)^2 -> 0.000256 | T28: =ABS(K23-AVERAGE(K$22:K$31))^2 -> 1.089e-05 | V28: =abs(L23-V$23)^2 -> 0 | W28: =ABS(L23-AVERAGE(L$22:L$31))^2 -> 1.681e-05
I29: 8 | J29: =C12-I$20 -> 0.194 | K29: =D12-J$20 -> 0.114 | L29: =E12-K$20 -> 0.056 | M29: =(J29*K29*L29)*N$20 -> 1.238496 | O29: 3 | P29: =abs(J24-Q$23)^2 -> 4e-06 | Q29: =ABS(J24-AVERAGE(J$22:J$31))^2 -> 1.156e-05 | S29: =abs(K24-S$23)^2 -> 0.0001 | T29: =ABS(K24-AVERAGE(K$22:K$31))^2 -> 7.29e-06 | V29: =abs(L24-V$23)^2 -> 0.000289 | W29: =ABS(L24-AVERAGE(L$22:L$31))^2 -> 0.00016641
I30: 9 | J30: =C13-I$20 -> 0.194 | K30: =D13-J$20 -> 0.112 | L30: =E13-K$20 -> 0.055 | M30: =(J30*K30*L30)*N$20 -> 1.19504 | O30: 4 | P30: =abs(J25-Q$23)^2 -> 0 | Q30: =ABS(J25-AVERAGE(J$22:J$31))^2 -> 1.96e-06 | S30: =abs(K25-S$23)^2 -> 6.4e-05 | T30: =ABS(K25-AVERAGE(K$22:K$31))^2 -> 2.209e-05 | V30: =abs(L25-V$23)^2 -> 1e-06 | W30: =ABS(L25-AVERAGE(L$22:L$31))^2 -> 9.61e-06
I31: 10 | J31: =C14-I$20 -> 0.192 | K31: =D14-J$20 -> 0.118 | L31: =E14-K$20 -> 0.054 | M31: =(J31*K31*L31)*N$20 -> 1.223424 | O31: 5 | P31: =abs(J26-Q$23)^2 -> 0.0009 | Q31: =ABS(J26-AVERAGE(J$22:J$31))^2 -> 0.00081796 | S31: =abs(K26-S$23)^2 -> 0.000169 | T31: =ABS(K26-AVERAGE(K$22:K$31))^2 -> 9e-08 | V31: =abs(L26-V$23)^2 -> 0 | W31: =ABS(L26-AVERAGE(L$22:L$31))^2 -> 1.681e-05
O32: 6 | P32: =abs(J27-Q$23)^2 -> 9e-06 | Q32: =ABS(J27-AVERAGE(J$22:J$31))^2 -> 1.936e-05 | S32: =abs(K27-S$23)^2 -> 0.000121 | T32: =ABS(K27-AVERAGE(K$22:K$31))^2 -> 2.89e-06 | V32: =abs(L27-V$23)^2 -> 3.6e-05 | W32: =ABS(L27-AVERAGE(L$22:L$31))^2 -> 3.61e-06
O33: 7 | P33: =abs(J28-Q$23)^2 -> 2.5e-05 | Q33: =ABS(J28-AVERAGE(J$22:J$31))^2 -> 1.296e-05 | S33: =abs(K28-S$23)^2 -> 0.0001 | T33: =ABS(K28-AVERAGE(K$22:K$31))^2 -> 7.29e-06 | V33: =abs(L28-V$23)^2 -> 3.6e-05 | W33: =ABS(L28-AVERAGE(L$22:L$31))^2 -> 3.61e-06
O34: 8 | P34: =abs(J29-Q$23)^2 -> 3.6e-05 | Q34: =ABS(J29-AVERAGE(J$22:J$31))^2 -> 5.476e-05 | S34: =abs(K29-S$23)^2 -> 0.000196 | T34: =ABS(K29-AVERAGE(K$22:K$31))^2 -> 1.69e-06 | V34: =abs(L29-V$23)^2 -> 3.6e-05 | W34: =ABS(L29-AVERAGE(L$22:L$31))^2 -> 3.61e-06
O35: 9 | P35: =abs(J30-Q$23)^2 -> 3.6e-05 | Q35: =ABS(J30-AVERAGE(J$22:J$31))^2 -> 5.476e-05 | S35: =abs(K30-S$23)^2 -> 0.000144 | T35: =ABS(K30-AVERAGE(K$22:K$31))^2 -> 4.9e-07 | V35: =abs(L30-V$23)^2 -> 2.5e-05 | W35: =ABS(L30-AVERAGE(L$22:L$31))^2 -> 8.1e-07
O36: 10 | P36: =abs(J31-Q$23)^2 -> 6.4e-05 | Q36: =ABS(J31-AVERAGE(J$22:J$31))^2 -> 8.836e-05 | S36: =abs(K31-S$23)^2 -> 0.000324 | T36: =ABS(K31-AVERAGE(K$22:K$31))^2 -> 2.809e-05 | V36: =abs(L31-V$23)^2 -> 1.6e-05 | W36: =ABS(L31-AVERAGE(L$22:L$31))^2 -> 1e-08
O37: Total | P37: =SUM(P27:P36) -> 0.001132 | Q37: =SUM(Q27:Q36) -> 0.0011124 | S37: =SUM(S27:S36) -> 0.001699 | T37: =SUM(T27:T36) -> 8.61e-05 | V37: =SUM(V27:V36) -> 0.000455 | W37: =SUM(W27:W36) -> 0.0002869
O38: MSE (m) | P38: =AVERAGE(P27:P36) -> 0.0001132 | Q38: =AVERAGE(Q27:Q36) -> 0.00011124 | S38: =AVERAGE(S27:S36) -> 0.0001699 | T38: =AVERAGE(T27:T36) -> 8.61e-06 | V38: =AVERAGE(V27:V36) -> 4.55e-05 | W38: =AVERAGE(W27:W36) -> 2.869e-05
K43: manual volume (L) = | L43: 1
C44: volume (L) manual | D44: 1
A45: Attempt number | B45: Calculated volume (L) | C45: Absolute Error (L) | D45: Standard Deviation (L) | E45: Execution time (s) | F45: Column 1 | G45: Attempt number | H45: Calculated volume (L) | I45: Quadratic Error (L) | J45: Standard Deviation (L) | K45: Execution time (s) | L45: MAPE Vol
A46: 1 | B46: =F5 -> 1.238 | C46: =abs(B46-D$44)^2 -> 0.056644 | D46: =(B46-B$56)^2 -> 0.00119025 | E46: =B5 -> 0.09 | G46: 1 | H46: =M22 -> 1.04213 | I46: =abs(H46-L$43)^2 -> 0.0017749369 | J46: =ABS(H46-H$56/10)^2 -> 0.033346485 | K46: =B5 -> 0.09 | L46: =ABS(L$43-H46)/L$43 -> 0.04213
A47: 2 | B47: =F6 -> 1.225 | C47: =abs(B47-D$44)^2 -> 0.050625 | D47: =(B47-B$56)^2 -> 0.00225625 | E47: =B6 -> 0.1 | G47: 2 | H47: =M23 -> 1.2006 | I47: =abs(H47-L$43)^2 -> 0.04024036 | J47: =ABS(H47-H$56/10)^2 -> 0.00058274926 | K47: =B6 -> 0.1 | L47: =ABS(L$43-H47)/L$43 -> 0.2006
A48: 3 | B48: =F7 -> 1.503 | C48: =abs(B48-D$44)^2 -> 0.253009 | D48: =(B48-B$56)^2 -> 0.05313025 | E48: =B7 -> 0.09 | G48: 3 | H48: =M24 -> 1.45926 | I48: =abs(H48-L$43)^2 -> 0.21091975 | J48: =ABS(H48-H$56/10)^2 -> 0.054999537 | K48: =B7 -> 0.09 | L48: =ABS(L$43-H48)/L$43 -> 0.45926
A49: 4 | B49: =F8 -> 1.14 | C49: =abs(B49-D$44)^2 -> 0.0196 | D49: =(B49-B$56)^2 -> 0.01755625 | E49: =B8 -> 0.29 | G49: 4 | H49: =M25 -> 1.1016 | I49: =abs(H49-L$43)^2 -> 0.01032256 | J49: =ABS(H49-H$56/10)^2 -> 0.015163509 | K49: =B8 -> 0.29 | L49: =ABS(L$43-H49)/L$43 -> 0.1016
A50: 5 | B50: =F9 -> 1.331 | C50: =abs(B50-D$44)^2 -> 0.109561 | D50: =(B50-B$56)^2 -> 0.00342225 | E50: =B9 -> 0.1 | G50: 5 | H50: =M26 -> 1.2995 | I50: =abs(H50-L$43)^2 -> 0.08970025 | J50: =ABS(H50-H$56/10)^2 -> 0.0055890277 | K50: =B9 -> 0.1 | L50: =ABS(L$43-H50)/L$43 -> 0.2995
...

Sheet Package 2 Evolution
A2: Note: The tables in this frame represent estimated values, plus a 5 mm precision adjustment implemented in the algorithm.
A4: Type of acquisition | B4: Execution Time (s) | C4: Length (m) | D4: Width (m) | E4: Height (m) | F4: Volume (L)
A5: MRS | B5: 0.21 | C5: 0.25 | D5: 0.158 | E5: 0.099 | F5: 3.89
A6: MRS | B6: 0.22 | C6: 0.26 | D6: 0.164 | E6: 0.1 | F6: 4.248
A7: MRS | B7: 0.11 | C7: 0.247 | D7: 0.154 | E7: 0.096 | F7: 3.65
A8: MRS | B8: 0.22 | C8: 0.258 | D8: 0.159 | E8: 0.097 | F8: 4
A9: MRS | B9: 0.1 | C9: 0.246 | D9: 0.166 | E9: 0.098 | F9: 3.983
A10: MRS | B10: 0.14 | C10: 0.247 | D10: 0.164 | E10: 0.099 | F10: 3.992
A11: MRS | B11: 0.18 | C11: 0.263 | D11: 0.168 | E11: 0.091 | F11: 4.012
A12: MRS | B12: 0.16 | C12: 0.255 | D12: 0.168 | E12: 0.092 | F12: 3.959
A13: MRS | B13: 0.29 | C13: 0.248 | D13: 0.16 | E13: 0.099 | F13: 3.922
A14: MRS | B14: 0.17 | C14: 0.253 | D14: 0.17 | E14: 0.099 | F14: 4.257
A15: CR3 - Alone | B15: 0.2 | C15: 0.258 | D15: 0.168 | E15: 0.097 | F15: 4.199
A16: CR3 - Alone | B16: 0.2 | C16: 0.264 | D16: 0.169 | E16: 0.097 | F16: 4.346
... A18: CR3 - Alone | B18: 0.19 | C18: 0.255 | D18: 0.167 | E18: 0.098 | F18: 4.178
A19: CR3 - Alone | B19: 0.16 | C19: 0.254 | D19: 0.16 | E19: 0.097 | F19: 3.932 | J19: Note: The tables in this frame represent the estimated actual values, disregarding the 5 mm precision adjustment in the algorithm.
H20: Precision adjustment (m)= | I20: 0.005 | M20: Conversion factor (L) = | N20: 1000
I21: Attempt | J21: Length (mm) | K21: Width (m) | L21: Height (m) | M21: Volume (L) | P21: Manual measurements
I22: 1 | J22: =C5-$I$20 -> 0.245 | K22: =D5-$I$20 -> 0.153 | L22: =E5-$I$20 -> 0.094 | M22: =(J22*K22*L22)*N$20 -> 3.52359 | P22: Length (m) | S22: Width (m) | V22: Height (m)
I23: 2 | J23: =C6-$I$20 -> 0.255 | K23: =D6-$I$20 -> 0.159 | L23: =E6-$I$20 -> 0.095 | M23: =(J23*K23*L23)*N$20 -> 3.851775 | Q23: 0.25 | S23: 0.15 | V23: 0.1
I24: 3 | J24: =C7-$I$20 -> 0.242 | K24: =D7-$I$20 -> 0.149 | L24: =E7-$I$20 -> 0.091 | M24: =(J24*K24*L24)*N$20 -> 3.281278 | P24: Mean squared error and standard deviation of the estimated box dimensions.
I25: 4 | J25: =C8-$I$20 -> 0.253 | K25: =D8-$I$20 -> 0.154 | L25: =E8-$I$20 -> 0.092 | M25: =(J25*K25*L25)*N$20 -> 3.584504 | P25: Length | S25: Width | V25: Height
I26: 5 | J26: =C9-$I$20 -> 0.241 | K26: =D9-$I$20 -> 0.161 | L26: =E9-$I$20 -> 0.093 | M26: =(J26*K26*L26)*N$20 -> 3.608493 | O26: Attempt | P26: SE (m) | Q26: Standard Deviation (m) | S26: SE (m) | T26: Standard Deviation (m) | V26: SE (m) | W26: Standard Deviation (m)
I27: 6 | J27: =C10-$I$20 -> 0.242 | K27: =D10-$I$20 -> 0.159 | L27: =E10-$I$20 -> 0.094 | M27: =(J27*K27*L27)*N$20 -> 3.616932 | O27: 1 | P27: =abs(J22-Q$23)^2 -> 2.5e-05 | Q27: =ABS(J22-AVERAGEA(J$22:J$36))^2 -> 1.9951111e-05 | S27: =abs(K22-S$23)^2 -> 9e-06 | T27: =ABS(K22-AVERAGEA(K$22:K$36))^2 -> 3.2871111e-05 | V27: =abs(L22-V$23)^2 -> 3.6e-05 | W27: =ABS(L22-AVERAGEA(L$22:L$36))^2 -> 3.7377778e-06
I28: 7 | J28: =C11-$I$20 -> 0.258 | K28: =D11-$I$20 -> 0.163 | L28: =E11-$I$20 -> 0.086 | M28: =(J28*K28*L28)*N$20 -> 3.616644 | O28: 2 | P28: =abs(J23-Q$23)^2 -> 2.5e-05 | Q28: =ABS(J23-AVERAGEA(J$22:J$36))^2 -> 3.0617778e-05 | S28: =abs(K23-S$23)^2 -> 8.1e-05 | T28: =ABS(K23-AVERAGEA(K$22:K$36))^2 -> 7.1111111e-08 | V28: =abs(L23-V$23)^2 -> 2.5e-05 | W28: =ABS(L23-AVERAGEA(L$22:L$36))^2 -> 8.6044444e-06
I29: 8 | J29: =C12-$I$20 -> 0.25 | K29: =D12-$I$20 -> 0.163 | L29: =E12-$I$20 -> 0.087 | M29: =(J29*K29*L29)*N$20 -> 3.54525 | O29: 3 | P29: =abs(J24-Q$23)^2 -> 6.4e-05 | Q29: =ABS(J24-AVERAGEA(J$22:J$36))^2 -> 5.5751111e-05 | S29: =abs(K24-S$23)^2 -> 1e-06 | T29: =ABS(K24-AVERAGEA(K$22:K$36))^2 -> 9.4737778e-05 | V29: =abs(L24-V$23)^2 -> 8.1e-05 | W29: =ABS(L24-AVERAGEA(L$22:L$36))^2 -> 1.1377778e-06
I30: 9 | J30: =C13-$I$20 -> 0.243 | K30: =D13-$I$20 -> 0.155 | L30: =E13-$I$20 -> 0.094 | M30: =(J30*K30*L30)*N$20 -> 3.54051 | O30: 4 | P30: =abs(J25-Q$23)^2 -> 9e-06 | Q30: =ABS(J25-AVERAGEA(J$22:J$36))^2 -> 1.2484444e-05 | S30: =abs(K25-S$23)^2 -> 1.6e-05 | T30: =ABS(K25-AVERAGEA(K$22:K$36))^2 -> 2.2404444e-05 | V30: =abs(L25-V$23)^2 -> 6.4e-05 | W30: =ABS(L25-AVERAGEA(L$22:L$36))^2 -> 4.4444444e-09
I31: 10 | J31: =C14-$I$20 -> 0.248 | K31: =D14-$I$20 -> 0.165 | L31: =E14-$I$20 -> 0.094 | M31: =(J31*K31*L31)*N$20 -> 3.84648 | O31: 5 | P31: =abs(J26-Q$23)^2 -> 8.1e-05 | Q31: =ABS(J26-AVERAGEA(J$22:J$36))^2 -> 7.1684444e-05 | S31: =abs(K26-S$23)^2 -> 0.000121 | T31: =ABS(K26-AVERAGEA(K$22:K$36))^2 -> 5.1377778e-06 | V31: =abs(L26-V$23)^2 -> 4.9e-05 | W31: =ABS(L26-AVERAGEA(L$22:L$36))^2 -> 8.7111111e-07
I32: 11 | J32: =C15-$I$20 -> 0.253 | K32: =D15-$I$20 -> 0.163 | L32: =E15-$I$20 -> 0.092 | M32: =(J32*K32*L32)*N$20 -> 3.793988 | O32: 6 | P32: =abs(J27-Q$23)^2 -> 6.4e-05 | Q32: =ABS(J27-AVERAGEA(J$22:J$36))^2 -> 5.5751111e-05 | S32: =abs(K27-S$23)^2 -> 8.1e-05 | T32: =ABS(K27-AVERAGEA(K$22:K$36))^2 -> 7.1111111e-08 | V32: =abs(L27-V$23)^2 -> 3.6e-05 | W32: =ABS(L27-AVERAGEA(L$22:L$36))^2 -> 3.7377778e-06
I33: 12 | J33: =C16-$I$20 -> 0.259 | K33: =D16-$I$20 -> 0.164 | L33: =E16-$I$20 -> 0.092 | M33: =(J33*K33*L33)*N$20 -> 3.907792 | O33: 7 | P33: =abs(J28-Q$23)^2 -> 6.4e-05 | Q33: =ABS(J28-AVERAGEA(J$22:J$36))^2 -> 7.2817778e-05 | S33: =abs(K28-S$23)^2 -> 0.000169 | T33: =ABS(K28-AVERAGEA(K$22:K$36))^2 -> 1.8204444e-05 | V33: =abs(L28-V$23)^2 -> 0.000196 | W33: =ABS(L28-AVERAGEA(L$22:L$36))^2 -> 3.6804444e-05
I34: 13 | J34: =C17-$I$20 -> 0.254 | K34: =D17-$I$20 -> 0.156 | L34: =E17-$I$20 -> 0.092 | M34: =(J34*K34*L34)*N$20 -> 3.645408 | O34: 8 | P34: =abs(J29-Q$23)^2 -> 0 | Q34: =ABS(J29-AVERAGEA(J$22:J$36))^2 -> 2.8444444e-07 | S34: =abs(K29-S$23)^2 -> 0.000169 | T34: =ABS(K29-AVERAGEA(K$22:K$36))^2 -> 1.8204444e-05 | V34: =abs(L29-V$23)^2 -> 0.000169 | W34: =ABS(L29-AVERAGEA(L$22:L$36))^2 -> 2.5671111e-05
I35: 14 | J35: =C18-$I$20 -> 0.25 | K35: =D18-$I$20 -> 0.162 | L35: =E18-$I$20 -> 0.093 | M35: =(J35*K35*L35)*N$20 -> 3.7665 | O35: 9 | P35: =abs(J30-Q$23)^2 -> 4.9e-05 | Q35: =ABS(J30-AVERAGEA(J$22:J$36))^2 -> 4.1817778e-05 | S35: =abs(K30-S$23)^2 -> 2.5e-05 | T35: =ABS(K30-AVERAGEA(K$22:K$36))^2 -> 1.3937778e-05 | V35: =abs(L30-V$23)^2 -> 3.6e-05 | W35: =ABS(L30-AVERAGEA(L$22:L$36))^2 -> 3.7377778e-06
I36: 15 | J36: =C19-$I$20 -> 0.249 | K36: =D19-$I$20 -> 0.155 | L36: =E19-$I$20 -> 0.092 | M36: =(J36*K36*L36)*N$20 -> 3.55074 | O36: 10 | P36: =abs(J31-Q$23)^2 -> 4e-06 | Q36: =ABS(J31-AVERAGEA(J$22:J$36))^2 -> 2.1511111e-06 | S36: =abs(K31-S$23)^2 -> 0.000225 | T36: =ABS(K31-AVERAGEA(K$22:K$36))^2 -> 3.9271111e-05 | V36: =abs(L31-V$23)^2 -> 3.6e-05 | W36: =ABS(L31-AVERAGEA(L$22:L$36))^2 -> 3.7377778e-06
O37: 11 | P37: =abs(J32-Q$23)^2 -> 9e-06 | Q37: =ABS(J32-AVERAGEA(J$22:J$36))^2 -> 1.2484444e-05 | S37: =abs(K32-S$23)^2 -> 0.000169 | T37: =ABS(K32-AVERAGEA(K$22:K$36))^2 -> 1.8204444e-05 | V37: =abs(L32-V$23)^2 -> 6.4e-05 | W37: =ABS(L32-AVERAGEA(L$22:L$36))^2 -> 4.4444444e-09
O38: 12 | P38: =abs(J33-Q$23)^2 -> 8.1e-05 | Q38: =ABS(J33-AVERAGEA(J$22:J$36))^2 -> 9.0884444e-05 | S38: =abs(K33-S$23)^2 -> 0.000196 | T38: =ABS(K33-AVERAGEA(K$22:K$36))^2 -> 2.7737778e-05 | V38: =abs(L33-V$23)^2 -> 6.4e-05 | W38: =ABS(L33-AVERAGEA(L$22:L$36))^2 -> 4.4444444e-09
O39: 13 | P39: =abs(J34-Q$23)^2 -> 1.6e-05 | Q39: =ABS(J34-AVERAGEA(J$22:J$36))^2 -> 2.0551111e-05 | S39: =abs(K34-S$23)^2 -> 3.6e-05 | T39: =ABS(K34-AVERAGEA(K$22:K$36))^2 -> 7.4711111e-06 | V39: =abs(L34-V$23)^2 -> 6.4e-05 | W39: =ABS(L34-AVERAGEA(L$22:L$36))^2 -> 4.4444444e-09
C40: Manual volume (L) | D40: 3.75 | O40: 14 | P40: =abs(J35-Q$23)^2 -> 0 | Q40: =ABS(J35-AVERAGEA(J$22:J$36))^2 -> 2.8444444e-07 | S40: =abs(K35-S$23)^2 -> 0.000144 | T40: =ABS(K35-AVERAGEA(K$22:K$36))^2 -> 1.0671111e-05 | V40: =abs(L35-V$23)^2 -> 4.9e-05 | W40: =ABS(L35-AVERAGEA(L$22:L$36))^2 -> 8.7111111e-07
O41: 15 | P41: =abs(J36-Q$23)^2 -> 1e-06 | Q41: =ABS(J36-AVERAGEA(J$22:J$36))^2 -> 2.1777778e-07 | S41: =abs(K36-S$23)^2 -> 2.5e-05 | T41: =ABS(K36-AVERAGEA(K$22:K$36))^2 -> 1.3937778e-05 | V41: =abs(L36-V$23)^2 -> 6.4e-05 | W41: =ABS(L36-AVERAGEA(L$22:L$36))^2 -> 4.4444444e-09
A42: Attempt number | B42: Number of points | C42: Calculated volume (L) | D42: Absolute error (L) | E42: Standard deviation (L) | F42: Execution time (s) | O42: Total | P42: =SUM(P27:P41) -> 0.000492 | Q42: =SUM(Q27:Q41) -> 0.00048773333 | S42: =SUM(S27:S41) -> 0.001467 | T42: =SUM(T27:T41) -> 0.00032293333 | V42: =SUM(V27:V41) -> 0.001033 | W42: =SUM(W27:W41) -> 8.8933333e-05
A43: 1 | C43: =F5 -> 3.89 | D43: =abs(C43-D$40)^2 -> 0.0196 | E43: =(C43-C$58)^2 -> 0.025944005 | F43: =B5 -> 0.21 | J43: manual volume (L) = | K43: 3.75 | O43: MSE (m) | P43: =P42/15 -> 3.28e-05 | Q43: =Q42/15 -> 3.2515556e-05 | S43: =S42/15 -> 9.78e-05 | T43: =T42/15 -> 2.1528889e-05 | V43: =V42/15 -> 6.8866667e-05 | W43: =W42/15 -> 5.9288889e-06
...

Sheet Package 3 Evolution
A2: Note: The tables in this frame represent estimated values, plus a 5 mm precision adjustment implemented in the algorithm.
A4: Type of acquisition | B4: Execution Time (s) | C4: Length (m) | D4: Width (m) | E4: Height (m) | F4: Volume
A5: MRS | B5: 0.17 | C5: 0.312 | D5: 0.219 | E5: 0.105 | F5: 7.156
A6: MRS | B6: 0.35 | C6: 0.308 | D6: 0.21 | E6: 0.099 | F6: 6.428
A7: MRS | B7: 0.25 | C7: 0.302 | D7: 0.214 | E7: 0.098 | F7: 6.345
A8: MRS | B8: 0.31 | C8: 0.321 | D8: 0.227 | E8: 0.093 | F8: 6.774
A9: MRS | B9: 0.28 | C9: 0.33 | D9: 0.188 | E9: 0.097 | F9: 6.009
A10: MRS | B10: 0.24 | C10: 0.299 | D10: 0.225 | E10: 0.098 | F10: 6.612
A11: MRS | B11: 0.17 | C11: 0.298 | D11: 0.194 | E11: 0.094 | F11: 5.466
A12: CR3 - Alone | B12: 0.27 | C12: 0.302 | D12: 0.219 | E12: 0.1 | F12: 6.599
A13: CR3 - Alone | B13: 0.29 | C13: 0.312 | D13: 0.215 | E13: 0.099 | F13: 6.628
A14: CR3 - Alone | B14: 0.23 | C14: 0.299 | D14: 0.22 | E14: 0.097 | F14: 6.409
A15: CR3 - Alone | B15: 0.33 | C15: 0.302 | D15: 0.209 | E15: 0.099 | F15: 6.244
A16: CR3 - Alone | B16: 0.19 | C16: 0.297 | D16: 0.213 | E16: 0.097 | F16: 6.151
J19: Note: The tables in this frame represent the estimated actual values, disregarding the 5 mm precision adjustment in the algorithm.
H20: Precision adjustment (m)= | I20: 0.005 | M20: Conversion factor (L) = | N20: 1000
I21: Attempt | J21: Length (m) | K21: Width (m) | L21: Height (m) | M21: Volume (L) | P21: Manual measurements
I22: 1 | J22: =C5-$I$20 -> 0.307 | K22: =D5-$I$20 -> 0.214 | L22: =E5-$I$20 -> 0.1 | M22: =(J22*K22*L22)*N$20 -> 6.5698 | P22: Length (m) | S22: Width (m) | V22: Height (m)
I23: 2 | J23: =C6-$I$20 -> 0.303 | K23: =D6-$I$20 -> 0.205 | L23: =E6-$I$20 -> 0.094 | M23: =(J23*K23*L23)*N$20 -> 5.83881 | Q23: 0.3 | S23: 0.2 | V23: 0.1
I24: 3 | J24: =C7-$I$20 -> 0.297 | K24: =D7-$I$20 -> 0.209 | L24: =E7-$I$20 -> 0.093 | M24: =(J24*K24*L24)*N$20 -> 5.772789 | P24: Mean squared error and standard deviation of the estimated box dimensions.
I25: 4 | J25: =C8-$I$20 -> 0.316 | K25: =D8-$I$20 -> 0.222 | L25: =E8-$I$20 -> 0.088 | M25: =(J25*K25*L25)*N$20 -> 6.173376 | P25: Length | S25: Width | V25: Height
I26: 5 | J26: =C9-$I$20 -> 0.325 | K26: =D9-$I$20 -> 0.183 | L26: =E9-$I$20 -> 0.092 | M26: =(J26*K26*L26)*N$20 -> 5.4717 | O26: Attempt | P26: SE (m) | Q26: Standard Deviation (m) | S26: SE (m) | T26: Standard Deviation (m) | V26: SE (m) | W26: Standard Deviation (m)
I27: 6 | J27: =C10-$I$20 -> 0.294 | K27: =D10-$I$20 -> 0.22 | L27: =E10-$I$20 -> 0.093 | M27: =(J27*K27*L27)*N$20 -> 6.01524 | O27: 1 | P27: =abs(J22-Q$23)^2 -> 4.9e-05 | Q27: =ABS(J22-AVERAGE(J$22:J$33))^2 -> 2.6694444e-05 | S27: =abs(K22-S$23)^2 -> 0.000196 | T27: =ABS(K22-AVERAGE(K$22:K$33))^2 -> 3.90625e-05 | V27: =abs(L22-V$23)^2 -> 0 | W27: =ABS(L22-AVERAGE(L$22:L$33))^2 -> 4.9e-05
I28: 7 | J28: =C11-$I$20 -> 0.293 | K28: =D11-$I$20 -> 0.189 | L28: =E11-$I$20 -> 0.089 | M28: =(J28*K28*L28)*N$20 -> 4.928553 | O28: 2 | P28: =abs(J23-Q$23)^2 -> 9e-06 | Q28: =ABS(J23-AVERAGE(J$22:J$33))^2 -> 1.3611111e-06 | S28: =abs(K23-S$23)^2 -> 2.5e-05 | T28: =ABS(K23-AVERAGE(K$22:K$33))^2 -> 7.5625e-06 | V28: =abs(L23-V$23)^2 -> 3.6e-05 | W28: =ABS(L23-AVERAGE(L$22:L$33))^2 -> 1e-06
I29: 8 | J29: =C12-$I$20 -> 0.297 | K29: =D12-$I$20 -> 0.214 | L29: =E12-$I$20 -> 0.095 | M29: =(J29*K29*L29)*N$20 -> 6.03801 | O29: 3 | P29: =abs(J24-Q$23)^2 -> 9e-06 | Q29: =ABS(J24-AVERAGE(J$22:J$33))^2 -> 2.3361111e-05 | S29: =abs(K24-S$23)^2 -> 8.1e-05 | T29: =ABS(K24-AVERAGE(K$22:K$33))^2 -> 1.5625e-06 | V29: =abs(L24-V$23)^2 -> 4.9e-05 | W29: =ABS(L24-AVERAGE(L$22:L$33))^2 -> 0
I30: 9 | J30: =C13-$I$20 -> 0.307 | K30: =D13-$I$20 -> 0.21 | L30: =E13-$I$20 -> 0.094 | M30: =(J30*K30*L30)*N$20 -> 6.06018 | O30: 4 | P30: =abs(J25-Q$23)^2 -> 0.000256 | Q30: =ABS(J25-AVERAGE(J$22:J$33))^2 -> 0.00020069444 | S30: =abs(K25-S$23)^2 -> 0.000484 | T30: =ABS(K25-AVERAGE(K$22:K$33))^2 -> 0.0002030625 | V30: =abs(L25-V$23)^2 -> 0.000144 | W30: =ABS(L25-AVERAGE(L$22:L$33))^2 -> 2.5e-05
I31: 10 | J31: =C14-$I$20 -> 0.294 | K31: =D14-$I$20 -> 0.215 | L31: =E14-$I$20 -> 0.092 | M31: =(J31*K31*L31)*N$20 -> 5.81532 | O31: 5 | P31: =abs(J26-Q$23)^2 -> 0.000625 | Q31: =ABS(J26-AVERAGE(J$22:J$33))^2 -> 0.00053669444 | S31: =abs(K26-S$23)^2 -> 0.000289 | T31: =ABS(K26-AVERAGE(K$22:K$33))^2 -> 0.0006125625 | V31: =abs(L26-V$23)^2 -> 6.4e-05 | W31: =ABS(L26-AVERAGE(L$22:L$33))^2 -> 1e-06
I32: 11 | J32: =C15-$I$20 -> 0.297 | K32: =D15-$I$20 -> 0.204 | L32: =E15-$I$20 -> 0.094 | M32: =(J32*K32*L32)*N$20 -> 5.695272 | O32: 6 | P32: =abs(J27-Q$23)^2 -> 3.6e-05 | Q32: =ABS(J27-AVERAGE(J$22:J$33))^2 -> 6.1361111e-05 | S32: =abs(K27-S$23)^2 -> 0.0004 | T32: =ABS(K27-AVERAGE(K$22:K$33))^2 -> 0.0001500625 | V32: =abs(L27-V$23)^2 -> 4.9e-05 | W32: =ABS(L27-AVERAGE(L$22:L$33))^2 -> 0
I33: 12 | J33: =C16-$I$20 -> 0.292 | K33: =D16-$I$20 -> 0.208 | L33: =E16-$I$20 -> 0.092 | M33: =(J33*K33*L33)*N$20 -> 5.587712 | O33: 7 | P33: =abs(J28-Q$23)^2 -> 4.9e-05 | Q33: =ABS(J28-AVERAGE(J$22:J$33))^2 -> 7.8027778e-05 | S33: =abs(K28-S$23)^2 -> 0.000121 | T33: =ABS(K28-AVERAGE(K$22:K$33))^2 -> 0.0003515625 | V33: =abs(L28-V$23)^2 -> 0.000121 | W33: =ABS(L28-AVERAGE(L$22:L$33))^2 -> 1.6e-05
O34: 8 | P34: =abs(J29-Q$23)^2 -> 9e-06 | Q34: =ABS(J29-AVERAGE(J$22:J$33))^2 -> 2.3361111e-05 | S34: =abs(K29-S$23)^2 -> 0.000196 | T34: =ABS(K29-AVERAGE(K$22:K$33))^2 -> 3.90625e-05 | V34: =abs(L29-V$23)^2 -> 2.5e-05 | W34: =ABS(L29-AVERAGE(L$22:L$33))^2 -> 4e-06
O35: 9 | P35: =abs(J30-Q$23)^2 -> 4.9e-05 | Q35: =ABS(J30-AVERAGE(J$22:J$33))^2 -> 2.6694444e-05 | S35: =abs(K30-S$23)^2 -> 0.0001 | T35: =ABS(K30-AVERAGE(K$22:K$33))^2 -> 5.0625e-06 | V35: =abs(L30-V$23)^2 -> 3.6e-05 | W35: =ABS(L30-AVERAGE(L$22:L$33))^2 -> 1e-06
O36: 10 | P36: =abs(J31-Q$23)^2 -> 3.6e-05 | Q36: =ABS(J31-AVERAGE(J$22:J$33))^2 -> 6.1361111e-05 | S36: =abs(K31-S$23)^2 -> 0.000225 | T36: =ABS(K31-AVERAGE(K$22:K$33))^2 -> 5.25625e-05 | V36: =abs(L31-V$23)^2 -> 6.4e-05 | W36: =ABS(L31-AVERAGE(L$22:L$33))^2 -> 1e-06
O37: 11 | P37: =abs(J32-Q$23)^2 -> 9e-06 | Q37: =ABS(J32-AVERAGE(J$22:J$33))^2 -> 2.3361111e-05 | S37: =abs(K32-S$23)^2 -> 1.6e-05 | T37: =ABS(K32-AVERAGE(K$22:K$33))^2 -> 1.40625e-05 | V37: =abs(L32-V$23)^2 -> 3.6e-05 | W37: =ABS(L32-AVERAGE(L$22:L$33))^2 -> 1e-06
O38: 12 | P38: =abs(J33-Q$23)^2 -> 6.4e-05 | Q38: =ABS(J33-AVERAGE(J$22:J$33))^2 -> 9.6694444e-05 | S38: =abs(K33-S$23)^2 -> 6.4e-05 | T38: =ABS(K33-AVERAGE(K$22:K$33))^2 -> 6.25e-08 | V38: =abs(L33-V$23)^2 -> 6.4e-05 | W38: =ABS(L33-AVERAGE(L$22:L$33))^2 -> 1e-06
O39: Total | P39: =SUM(P27:P38) -> 0.0012 | Q39: =SUM(Q27:Q38) -> 0.0011596667 | S39: =SUM(S27:S38) -> 0.002197 | T39: =SUM(T27:T38) -> 0.00147625 | V39: =SUM(V27:V38) -> 0.000688 | W39: =SUM(W27:W38) -> 0.0001
O40: MSE (m) | P40: =P39/12 -> 0.0001 | Q40: =Q39/12 -> 9.6638889e-05 | S40: =S39/12 -> 0.00018308333 | T40: =T39/12 -> 0.00012302083 | V40: =V39/12 -> 5.7333333e-05 | W40: =W39/12 -> 8.3333333e-06
J43: manual volume (L) = | K43: =(Q23*S23*V23)*N20 -> 6
I45: Attempt | J45: Calculated volume (L) | K45: Absolute Error (L) | L45: Standard Deviation (L) | M45: Execution time (s) | N45: MAPE Vol
I46: 1 | J46: =M22 -> 6.5698 | K46: =abs(J46-K$43)^2 -> 0.32467204 | L46: =ABS(J46-J$58/12)^2 -> 0.5464706 | M46: =B5 -> 0.17 | N46: =ABS(K$43-J46)/K$43 -> 0.094966667
I47: 2 | J47: =M23 -> 5.83881 | K47: =abs(J47-K$43)^2 -> 0.025982216 | L47: =ABS(J47-J$58/12)^2 -> 6.8004762e-05 | M47: =B6 -> 0.35 | N47: =ABS(K$43-J47)/K$43 -> 0.026865
...

Sheet Package 4 Evolution
A2: Note: The tables in this frame represent estimated values, plus a 5 mm precision adjustment implemented in the algorithm.
A4: Type of acquisition | B4: Execution Time (s) | C4: Length (m) | D4: Width (m) | E4: Height (m) | F4: Volume (L)
A5: MRS | B5: 0.09 | C5: 0.219 | D5: 0.23 | E5: 0.181 | F5: 9.17
A6: MRS | B6: 0.1 | C6: 0.194 | D6: 0.24 | E6: 0.177 | F6: 8.39
A7: MRS | B7: 0.21 | C7: 0.241 | D7: 0.229 | E7: 0.198 | F7: 10.896
A8: MRS | B8: 0.14 | C8: 0.216 | D8: 0.21 | E8: 0.18 | F8: 8.192
A9: CR3 - Alone | B9: 0.22 | C9: 0.231 | D9: 0.229 | E9: 0.194 | F9: 10.266
A10: CR3 - Alone | B10: 0.2 | C10: 0.229 | D10: 0.218 | E10: 0.19 | F10: 9.487
A11: CR3 - Alone | B11: 0.18 | C11: 0.231 | D11: 0.223 | E11: 0.191 | F11: 9.82
A12: CR3 - Alone | B12: 0.42 | C12: 0.215 | D12: 0.2 | E12: 0.191 | F12: 8.233
A13: CR3 - Alone | B13: 0.18 | C13: 0.22 | D13: 0.213 | E13: 0.189 | F13: 8.827
A14: CR3 - Alone | B14: 0.16 | C14: 0.212 | D14: 0.2 | E14: 0.191 | F14: 8.106
J17: Note: The tables in this frame represent the estimated actual values, disregarding the 5 mm precision adjustment in the algorithm.
H18: Precision adjustment (m)= | I18: 0.005 | M18: Conversion factor (L) = | N18: 1000
I19: Attempt | J19: Length (m) | K19: Width (m) | L19: Height (m) | M19: Volume (L) | P19: Manual measurements
I20: 1 | J20: =C5-$I$18 -> 0.214 | K20: =D5-$I$18 -> 0.225 | L20: =E5-$I$18 -> 0.176 | M20: =(J20*K20*L20)*N$18 -> 8.4744 | P20: Length (m) | S20: Width (m) | V20: Height (m)
I21: 2 | J21: =C6-$I$18 -> 0.189 | K21: =D6-$I$18 -> 0.235 | L21: =E6-$I$18 -> 0.172 | M21: =(J21*K21*L21)*N$18 -> 7.63938 | Q21: 0.2 | S21: 0.2 | V21: 0.2
I22: 3 | J22: =C7-$I$18 -> 0.236 | K22: =D7-$I$18 -> 0.224 | L22: =E7-$I$18 -> 0.193 | M22: =(J22*K22*L22)*N$18 -> 10.202752 | P22: Mean squared error and standard deviation of the estimated box dimensions.
I23: 4 | J23: =C8-$I$18 -> 0.211 | K23: =D8-$I$18 -> 0.205 | L23: =E8-$I$18 -> 0.175 | M23: =(J23*K23*L23)*N$18 -> 7.569625 | P23: Length | S23: Width | V23: Height
I24: 5 | J24: =C9-$I$18 -> 0.226 | K24: =D9-$I$18 -> 0.224 | L24: =E9-$I$18 -> 0.189 | M24: =(J24*K24*L24)*N$18 -> 9.567936 | O24: Attempt | P24: SE (m) | Q24: Standard Deviation (m) | S24: SE (m) | T24: Standard Deviation (m) | V24: SE (m) | W24: Standard Deviation (m)
I25: 6 | J25: =C10-$I$18 -> 0.224 | K25: =D10-$I$18 -> 0.213 | L25: =E10-$I$18 -> 0.185 | M25: =(J25*K25*L25)*N$18 -> 8.82672 | O25: 1 | P25: =abs(J20-Q$21)^2 -> 0.000196 | Q25: =ABS(J20-AVERAGE(J20:J29))^2 -> 3.24e-06 | S25: =abs(K20-S$21)^2 -> 0.000625 | T25: =ABS(K20-AVERAGE(K$20:K$29))^2 -> 0.00011664 | V25: =abs(L20-V$21)^2 -> 0.000576 | W25: =ABS(L20-AVERAGE(L$20:L$29))^2 -> 5.184e-05
I26: 7 | J26: =C11-$I$18 -> 0.226 | K26: =D11-$I$18 -> 0.218 | L26: =E11-$I$18 -> 0.186 | M26: =(J26*K26*L26)*N$18 -> 9.163848 | O26: 2 | P26: =abs(J21-Q$21)^2 -> 0.000121 | Q26: =ABS(J21-AVERAGE(J21:J30))^2 -> 0.000729 | S26: =abs(K21-S$21)^2 -> 0.001225 | T26: =ABS(K21-AVERAGE(K$20:K$29))^2 -> 0.00043264 | V26: =abs(L21-V$21)^2 -> 0.000784 | W26: =ABS(L21-AVERAGE(L$20:L$29))^2 -> 0.00012544
I27: 8 | J27: =C12-$I$18 -> 0.21 | K27: =D12-$I$18 -> 0.195 | L27: =E12-$I$18 -> 0.186 | M27: =(J27*K27*L27)*N$18 -> 7.6167 | O27: 3 | P27: =abs(J22-Q$21)^2 -> 0.001296 | Q27: =ABS(J22-AVERAGE(J22:J31))^2 -> 0.00027639062 | S27: =abs(K22-S$21)^2 -> 0.000576 | T27: =ABS(K22-AVERAGE(K$20:K$29))^2 -> 9.604e-05 | V27: =abs(L22-V$21)^2 -> 4.9e-05 | W27: =ABS(L22-AVERAGE(L$20:L$29))^2 -> 9.604e-05
I28: 9 | J28: =C13-$I$18 -> 0.215 | K28: =D13-$I$18 -> 0.208 | L28: =E13-$I$18 -> 0.184 | M28: =(J28*K28*L28)*N$18 -> 8.22848 | O28: 4 | P28: =abs(J23-Q$21)^2 -> 0.000121 | Q28: =ABS(J23-AVERAGE(J23:J32))^2 -> 3.6e-05 | S28: =abs(K23-S$21)^2 -> 2.5e-05 | T28: =ABS(K23-AVERAGE(K$20:K$29))^2 -> 8.464e-05 | V28: =abs(L23-V$21)^2 -> 0.000625 | W28: =ABS(L23-AVERAGE(L$20:L$29))^2 -> 6.724e-05
I29: 10 | J29: =C14-$I$18 -> 0.207 | K29: =D14-$I$18 -> 0.195 | L29: =E14-$I$18 -> 0.186 | M29: =(J29*K29*L29)*N$18 -> 7.50789 | O29: 5 | P29: =abs(J24-Q$21)^2 -> 0.000676 | Q29: =ABS(J24-AVERAGE(J24:J33))^2 -> 6.4e-05 | S29: =abs(K24-S$21)^2 -> 0.000576 | T29: =ABS(K24-AVERAGE(K$20:K$29))^2 -> 9.604e-05 | V29: =abs(L24-V$21)^2 -> 0.000121 | W29: =ABS(L24-AVERAGE(L$20:L$29))^2 -> 3.364e-05
O30: 6 | P30: =abs(J25-Q$21)^2 -> 0.000576 | Q30: =ABS(J25-AVERAGE(J25:J34))^2 -> 5.776e-05 | S30: =abs(K25-S$21)^2 -> 0.000169 | T30: =ABS(K25-AVERAGE(K$20:K$29))^2 -> 1.44e-06 | V30: =abs(L25-V$21)^2 -> 0.000225 | W30: =ABS(L25-AVERAGE(L$20:L$29))^2 -> 3.24e-06
O31: 7 | P31: =abs(J26-Q$21)^2 -> 0.000676 | Q31: =ABS(J26-AVERAGE(J26:J35))^2 -> 0.00013225 | S31: =abs(K26-S$21)^2 -> 0.000324 | T31: =ABS(K26-AVERAGE(K$20:K$29))^2 -> 1.444e-05 | V31: =abs(L26-V$21)^2 -> 0.000196 | W31: =ABS(L26-AVERAGE(L$20:L$29))^2 -> 7.84e-06
O32: 8 | P32: =abs(J27-Q$21)^2 -> 0.0001 | Q32: =ABS(J27-AVERAGE(J27:J36))^2 -> 4.4444444e-07 | S32: =abs(K27-S$21)^2 -> 2.5e-05 | T32: =ABS(K27-AVERAGE(K$20:K$29))^2 -> 0.00036864 | V32: =abs(L27-V$21)^2 -> 0.000196 | W32: =ABS(L27-AVERAGE(L$20:L$29))^2 -> 7.84e-06
O33: 9 | P33: =abs(J28-Q$21)^2 -> 0.000225 | Q33: =ABS(J28-AVERAGE(J28:J37))^2 -> 1.6e-05 | S33: =abs(K28-S$21)^2 -> 6.4e-05 | T33: =ABS(K28-AVERAGE(K$20:K$29))^2 -> 3.844e-05 | V33: =abs(L28-V$21)^2 -> 0.000256 | W33: =ABS(L28-AVERAGE(L$20:L$29))^2 -> 6.4e-07
O34: 10 | P34: =abs(J29-Q$21)^2 -> 4.9e-05 | Q34: =ABS(J29-AVERAGE(J29:J38))^2 -> 0 | S34: =abs(K29-S$21)^2 -> 2.5e-05 | T34: =ABS(K29-AVERAGE(K$20:K$29))^2 -> 0.00036864 | V34: =abs(L29-V$21)^2 -> 0.000196 | W34: =ABS(L29-AVERAGE(L$20:L$29))^2 -> 7.84e-06
O35: Total | P35: =SUM(P25:P34) -> 0.004036 | Q35: =SUM(Q25:Q34) -> 0.0013150851 | S35: =SUM(S25:S34) -> 0.003634 | T35: =SUM(T25:T34) -> 0.0016176 | V35: =SUM(V25:V34) -> 0.003224 | W35: =SUM(W25:W34) -> 0.0004016
O36: MSE (m) | P36: =P35/10 -> 0.0004036 | Q36: =Q35/10 -> 0.00013150851 | S36: =S35/10 -> 0.0003634 | T36: =T35/10 -> 0.00016176 | V36: =V35/10 -> 0.0003224 | W36: =W35/10 -> 4.016e-05
J39: manual volume (L) = | K39: 8
I41: Attempt | J41: Calculated volume (L) | K41: RMSE (L) | L41: Standard Deviation (L) | M41: Execution time (s) | N41: MAPE Vol
I42: 1 | J42: =M20 -> 8.4744 | K42: =abs(J42-K$39)^2 -> 0.22505536 | L42: =ABS(J42-J$52/10)^2 -> 2.8870204e-05 | M42: =B5 -> 0.09 | N42: =ABS(K$39-J42)/K$39 -> 0.0593
I43: 2 | J43: =M21 -> 7.63938 | K43: =abs(J43-K$39)^2 -> 0.13004678 | L43: =ABS(J43-J$52/10)^2 -> 0.70626056 | M43: =B6 -> 0.1 | N43: =ABS(K$39-J43)/K$39 -> 0.0450775
I44: 3 | J44: =M22 -> 10.202752 | K44: =abs(J44-K$39)^2 -> 4.8521164 | L44: =ABS(J44-J$52/10)^2 -> 2.9686563 | M44: =B7 -> 0.21 | N44: =ABS(K$39-J44)/K$39 -> 0.275344
I45: 4 | J45: =M23 -> 7.569625 | K45: =abs(J45-K$39)^2 -> 0.18522264 | L45: =ABS(J45-J$52/10)^2 -> 0.82836956 | M45: =B8 -> 0.14 | N45: =ABS(K$39-J45)/K$39 -> 0.053796875
I46: 5 | J46: =M24 -> 9.567936 | K46: =abs(J46-K$39)^2 -> 2.4584233 | L46: =ABS(J46-J$52/10)^2 -> 1.1840985 | M46: =B9 -> 0.22 | N46: =ABS(K$39-J46)/K$39 -> 0.195992
I47: 6 | J47: =M25 -> 8.82672 | K47: =abs(J47-K$39)^2 -> 0.68346596 | L47: =ABS(J47-J$52/10)^2 -> 0.12037215 | M47: =B10 -> 0.2 | N47: =ABS(K$39-J47)/K$39 -> 0.10334
...
